<?xml version="1.0" encoding="utf-8" ?>
<!-- This URDF was automatically created by SolidWorks to URDF Exporter! Originally created by Stephen Brawner (brawner@gmail.com) 
     Commit Version: 1.6.0-4-g7f85cfe  Build Version: 1.6.7995.38578
     For more information, please see http://wiki.ros.org/sw_urdf_exporter -->
<robot name="six_dofra_description">
    <link name="base_link">
        <inertial>
            <origin xyz="0.022817 0.049403 3.7314E-07" rpy="0 0 0" />
            <mass value="0.99277" />
            <inertia ixx="0.0020036" ixy="-0.00015881" ixz="-5.4195E-09" iyy="0.0044439" iyz="-2.3861E-10" izz="0.0029527" />
        </inertial>
        <visual>
            <origin xyz="0 0 0" rpy="0 0 0" />
            <geometry>
                <mesh filename="package://six_dofra_description/meshes/link_0.STL" />
            </geometry>
            <material name="">
                <color rgba="0.79216 0.81961 0.93333 1" />
            </material>
        </visual>
        <collision>
            <origin xyz="0 0 0" rpy="0 0 0" />
            <geometry>
                <mesh filename="package://six_dofra_description/meshes/link_0.STL" />
            </geometry>
        </collision>
    </link>
    <joint name="fixed_joint" type="fixed">
        <origin xyz="0 0 0.1" rpy="0 0 0" />
        <parent link="base_link" />
        <child link="link_1" />
        <axis xyz="0 0 0" />
    </joint>
    <link name="link_1">
        <inertial>
            <origin xyz="-0.038493 0.0097978 0.060588" rpy="0 0 0" />
            <mass value="0.98184" />
            <inertia ixx="0.0010908" ixy="-9.74E-05" ixz="0.00034553" iyy="0.0018074" iyz="7.0954E-05" izz="0.0017078" />
        </inertial>
        <visual>
            <origin xyz="0 0 0" rpy="0 0 0" />
            <geometry>
                <mesh filename="package://six_dofra_description/meshes/link_1.STL" />
            </geometry>
            <material name="">
                <color rgba="0.79216 0.81961 0.93333 1" />
            </material>
        </visual>
        <collision>
            <origin xyz="0 0 0" rpy="0 0 0" />
            <geometry>
                <mesh filename="package://six_dofra_description/meshes/link_1.STL" />
            </geometry>
        </collision>
    </link>
    <joint name="joint_1" type="revolute">
        <origin xyz="0 0.092795 0" rpy="-1.5708 0 0" />
        <parent link="base_link" />
        <child link="link_1" />
        <axis xyz="0 0 1" />
        <limit lower="-3.1416" upper="3.1416" effort="0" velocity="0" />
        <dynamics damping="0.01" friction="0.01" />
    </joint>
    <link name="link_2">
        <inertial>
            <origin xyz="2.3648E-05 0.096574 0.027873" rpy="0 0 0" />
            <mass value="0.42972" />
            <inertia ixx="0.00089288" ixy="-1.0303E-07" ixz="-4.4736E-08" iyy="0.00018276" iyz="2.4405E-05" izz="0.0010193" />
        </inertial>
        <visual>
            <origin xyz="0 0 0" rpy="0 0 0" />
            <geometry>
                <mesh filename="package://six_dofra_description/meshes/link_2.STL" />
            </geometry>
            <material name="">
                <color rgba="0.79216 0.81961 0.93333 1" />
            </material>
        </visual>
        <collision>
            <origin xyz="0 0 0" rpy="0 0 0" />
            <geometry>
                <mesh filename="package://six_dofra_description/meshes/link_2.STL" />
            </geometry>
        </collision>
    </link>
    <joint name="joint_2" type="revolute">
        <origin xyz="-0.0700000000000002 -0.0264909444637413 0.0882010969463582" rpy="1.5707963267949 0 0" />
        <parent link="link_1" />
        <child link="link_2" />
        <axis xyz="0 0 1" />
        <limit lower="-1.7453" upper="2.5307" effort="0" velocity="0" />
        <dynamics damping="0.01" friction="0.01" />
    </joint>
    <link name="link_3">
        <inertial>
            <origin xyz="-0.0242439731627712 0.01222934137209 0.0429988431408907" rpy="0 0 0" />
            <mass value="0.332912677350856" />
            <inertia ixx="0.000219724299078548" ixy="3.32243571175575E-06" ixz="3.22811740352238E-06" iyy="0.000139542421693531" iyz="-2.84256482328001E-05" izz="0.000169390504538882" />
        </inertial>
        <visual>
            <origin xyz="0 0 0" rpy="0 0 0" />
            <geometry>
                <mesh filename="package://six_dofra_description/meshes/link_3.STL" />
            </geometry>
            <material name="">
                <color rgba="0.792156862745098 0.819607843137255 0.933333333333333 1" />
            </material>
        </visual>
        <collision>
            <origin xyz="0 0 0" rpy="0 0 0" />
            <geometry>
                <mesh filename="package://six_dofra_description/meshes/link_3.STL" />
            </geometry>
        </collision>
    </link>
    <joint name="joint_3" type="revolute">
        <origin xyz="0 0.15 0" rpy="3.14159265358979 0 3.14159265358979" />
        <parent link="link_2" />
        <child link="link_3" />
        <axis xyz="0 0 1" />
        <limit lower="-3.1416" upper="3.1416" effort="0" velocity="0" />
        <dynamics damping="0.01" friction="0.01" />
    </joint>
    <link name="link_4">
        <inertial>
            <origin xyz="3.59874941199129E-05 -4.4233580096531E-06 0.0793180734125305" rpy="0 0 0" />
            <mass value="0.433556208010063" />
            <inertia ixx="0.00043478839151472" ixy="-3.05324416344868E-06" ixz="3.21839443025213E-07" iyy="0.000326743926124794" iyz="-1.28510846534109E-07" izz="0.0001784335160446" />
        </inertial>
        <visual>
            <origin xyz="0 0 0" rpy="0 0 0" />
            <geometry>
                <mesh filename="package://six_dofra_description/meshes/link_4.STL" />
            </geometry>
            <material name="">
                <color rgba="0.792156862745098 0.819607843137255 0.933333333333333 1" />
            </material>
        </visual>
        <collision>
            <origin xyz="0 0 0" rpy="0 0 0" />
            <geometry>
                <mesh filename="package://six_dofra_description/meshes/link_4.STL" />
            </geometry>
        </collision>
    </link>
    <joint name="joint_4" type="revolute">
        <origin xyz="0.0104999999999973 0.0349999999999985 0.0524909444637412" rpy="0 1.5707963267949 0" />
        <parent link="link_3" />
        <child link="link_4" />
        <axis xyz="0 0 -1" />
        <limit lower="-3.1416" upper="3.1416" effort="0" velocity="0" />
        <dynamics damping="0.01" friction="0.01" />
    </joint>
    <link name="link_5">
        <inertial>
            <origin xyz="1.82785163393984E-09 -1.98699304896355E-05 0.00734024876897377" rpy="0 0 0" />
            <mass value="0.0558248618031194" />
            <inertia ixx="1.47973820073645E-05" ixy="7.1288926964454E-13" ixz="5.8814895306997E-12" iyy="9.08387594285802E-06" iyz="-4.44650780264743E-09" izz="9.78331471020237E-06" />
        </inertial>
        <visual>
            <origin xyz="0 0 0" rpy="0 0 0" />
            <geometry>
                <mesh filename="package://six_dofra_description/meshes/link_5.STL" />
            </geometry>
            <material name="">
                <color rgba="0.792156862745098 0.819607843137255 0.933333333333333 1" />
            </material>
        </visual>
        <collision>
            <origin xyz="0 0 0" rpy="0 0 0" />
            <geometry>
                <mesh filename="package://six_dofra_description/meshes/link_5.STL" />
            </geometry>
        </collision>
    </link>
    <joint name="joint_5" type="revolute">
        <origin xyz="0 0 0.157500000000004" rpy="0 0 3.14159265358979" />
        <parent link="link_4" />
        <child link="link_5" />
        <axis xyz="1 0 0" />
        <limit lower="-3.1416" upper="3.1416" effort="0" velocity="0" />
        <dynamics damping="0.01" friction="0.01" />
    </joint>
    <link name="link_6">
        <inertial>
            <origin xyz="0 -4.16333634234434E-17 0.0067746717080025" rpy="0 0 0" />
            <mass value="0.00699961434313697" />
            <inertia ixx="7.10744988499904E-07" ixy="7.18131478686715E-22" ixz="8.39981245119167E-23" iyy="7.10744988499906E-07" iyz="-2.10277728819863E-21" izz="1.30114998340272E-06" />
        </inertial>
        <visual>
            <origin xyz="0 0 0" rpy="0 0 0" />
            <geometry>
                <mesh filename="package://six_dofra_description/meshes/link_6.STL" />
            </geometry>
            <material name="">
                <color rgba="1 1 1 0.25" />
            </material>
        </visual>
        <collision>
            <origin xyz="0 0 0" rpy="0 0 0" />
            <geometry>
                <mesh filename="package://six_dofra_description/meshes/link_6.STL" />
            </geometry>
        </collision>
    </link>
    <joint name="joint_6" type="revolute">
        <origin xyz="0 0 0.0265" rpy="0 0 -1.5707963267949" />
        <parent link="link_5" />
        <child link="link_6" />
        <axis xyz="0 0 1" />
        <limit lower="-3.1416" upper="3.1416" effort="0" velocity="0" />
        <dynamics damping="0.01" friction="0.01" />
    </joint>
    <transmission name="trans_linear_axis">
        <type>transmission_interface/SimpleTransmission</type>
        <joint name="linear_axis">
            <hardwareInterface>hardware_interface/PositionJointInterface</hardwareInterface>
        </joint>
        <actuator name="linear_axis_motor">
            <hardwareInterface>hardware_interface/PositionJointInterface</hardwareInterface>
            <mechanicalReduction>1</mechanicalReduction>
        </actuator>
    </transmission>
    <transmission name="trans_joint_1">
        <type>transmission_interface/SimpleTransmission</type>
        <joint name="joint_1">
            <hardwareInterface>hardware_interface/PositionJointInterface</hardwareInterface>
        </joint>
        <actuator name="joint_1_motor">
            <hardwareInterface>hardware_interface/PositionJointInterface</hardwareInterface>
            <mechanicalReduction>1</mechanicalReduction>
        </actuator>
    </transmission>
    <transmission name="trans_joint_2">
        <type>transmission_interface/SimpleTransmission</type>
        <joint name="joint_2">
            <hardwareInterface>hardware_interface/PositionJointInterface</hardwareInterface>
        </joint>
        <actuator name="joint_2_motor">
            <hardwareInterface>hardware_interface/PositionJointInterface</hardwareInterface>
            <mechanicalReduction>1</mechanicalReduction>
        </actuator>
    </transmission>
    <transmission name="trans_joint_3">
        <type>transmission_interface/SimpleTransmission</type>
        <joint name="joint_3">
            <hardwareInterface>hardware_interface/PositionJointInterface</hardwareInterface>
        </joint>
        <actuator name="joint_3_motor">
            <hardwareInterface>hardware_interface/PositionJointInterface</hardwareInterface>
            <mechanicalReduction>1</mechanicalReduction>
        </actuator>
    </transmission>
    <transmission name="trans_joint_4">
        <type>transmission_interface/SimpleTransmission</type>
        <joint name="joint_4">
            <hardwareInterface>hardware_interface/PositionJointInterface</hardwareInterface>
        </joint>
        <actuator name="joint_4_motor">
            <hardwareInterface>hardware_interface/PositionJointInterface</hardwareInterface>
            <mechanicalReduction>1</mechanicalReduction>
        </actuator>
    </transmission>
    <transmission name="trans_joint_5">
        <type>transmission_interface/SimpleTransmission</type>
        <joint name="joint_5">
            <hardwareInterface>hardware_interface/PositionJointInterface</hardwareInterface>
        </joint>
        <actuator name="joint_5_motor">
            <hardwareInterface>hardware_interface/PositionJointInterface</hardwareInterface>
            <mechanicalReduction>1</mechanicalReduction>
        </actuator>
    </transmission>
    <transmission name="trans_joint_6">
        <type>transmission_interface/SimpleTransmission</type>
        <joint name="joint_6">
            <hardwareInterface>hardware_interface/PositionJointInterface</hardwareInterface>
        </joint>
        <actuator name="joint_6_motor">
            <hardwareInterface>hardware_interface/PositionJointInterface</hardwareInterface>
            <mechanicalReduction>1</mechanicalReduction>
        </actuator>
    </transmission>
    <gazebo reference="linear_sledge">
        <material>Gazebo/Grey</material>
        <mu1>0.2</mu1>
        <mu2>0.2</mu2>
    </gazebo>
    <gazebo reference="base_link">
        <material>Gazebo/Grey</material>
        <mu1>0.2</mu1>
        <mu2>0.2</mu2>
    </gazebo>
    <gazebo reference="link_1">
        <material>Gazebo/Grey</material>
        <mu1>0.2</mu1>
        <mu2>0.2</mu2>
    </gazebo>
    <gazebo reference="link_2">
        <material>Gazebo/Grey</material>
        <mu1>0.2</mu1>
        <mu2>0.2</mu2>
    </gazebo>
    <gazebo reference="link_3">
        <material>Gazebo/Grey</material>
        <mu1>0.2</mu1>
        <mu2>0.2</mu2>
    </gazebo>
    <gazebo reference="link_4">
        <material>Gazebo/Grey</material>
        <mu1>0.2</mu1>
        <mu2>0.2</mu2>
    </gazebo>
    <gazebo reference="link_5">
        <material>Gazebo/Grey</material>
        <mu1>0.2</mu1>
        <mu2>0.2</mu2>
    </gazebo>
    <gazebo reference="link_6">
        <material>Gazebo/Grey</material>
        <mu1>0.2</mu1>
        <mu2>0.2</mu2>
    </gazebo>
    <!--Gazebo Plugins -->
    <gazebo>
        <plugin name="control" filename="libgazebo_ros_control.so">
        </plugin>
    </gazebo>
    <gazebo>
        <plugin name = "joint_state_publisher" filename = "libgazebo_ros_joint_state_publisher.so" >
		<jointName>linear_axis, joint_1, joint_2, joint_3, joint_4, joint_5, joint_6</jointName>
        </plugin>
    </gazebo>
</robot>
