<?xml version="1.0" encoding="utf-8"?>
<!-- This URDF was automatically created by SolidWorks to URDF Exporter! Originally created by Stephen Brawner (brawner@gmail.com) 
     Commit Version: 1.6.0-4-g7f85cfe  Build Version: 1.6.7995.38578
     For more information, please see http://wiki.ros.org/sw_urdf_exporter -->
<robot name="gripper" xmlns:xacro="http://www.ros.org/wiki/xacro">

  <!-- Gazebo transmission interface -->
  <xacro:include filename="$(find gripper)/urdf/gripper.transmission.xacro" />

  <xacro:macro name="gripper" params="prefix"> <!-- parent-->

  <!-- is good like this, but for test cases outcommented -->
    <!-- <joint name="${prefix}_base_joint" type="fixed">
      <parent link="${parent}"/>
      <child link="${prefix}_mount_link"/>
      <xacro:insert_block name="origin"/>
    </joint> -->

    <link
    name="${prefix}_mount_link">
    <inertial>
      <origin
        xyz="-7.69604728464136E-05 0.0135902117365988 0.0250753455696242"
        rpy="0 0 0" />
      <mass
        value="0.0572428949081024" />
      <inertia
        ixx="1.08739624685948E-05"
        ixy="-5.67703825246591E-08"
        ixz="-4.79892598221548E-12"
        iyy="1.32071568573059E-05"
        iyz="-2.91877769990152E-07"
        izz="1.6026956946386E-05" />
    </inertial>
    <visual>
      <origin
        xyz="0 0 0"
        rpy="0 0 0" />
      <geometry>
        <mesh
          filename="package://gripper/meshes/mount_link.STL" />
      </geometry>
      <material
        name="">
        <color
          rgba="1 1 1 1" />
      </material>
    </visual>
    <collision>
      <origin
        xyz="0 0 0"
        rpy="0 0 0" />
      <geometry>
        <mesh
          filename="package://gripper/meshes/mount_link.STL" />
      </geometry>
    </collision>
  </link>

  <link
    name="${prefix}_link_1_left">
    <inertial>
      <origin
        xyz="0.0201642304338692 1.38777878078145E-17 0.004236242137124"
        rpy="0 0 0" />
      <mass
        value="0.00469706452647219" />
      <inertia
        ixx="1.18042272673537E-07"
        ixy="2.48380401664581E-22"
        ixz="-6.12806042251421E-08"
        iyy="2.05310941947316E-06"
        iyz="-2.74480147325617E-24"
        izz="2.10931388717727E-06" />
    </inertial>
    <visual>
      <origin
        xyz="0 0 0"
        rpy="0 0 0" />
      <geometry>
        <mesh
          filename="package://gripper/meshes/link_1_left.STL" />
      </geometry>
      <material
        name="">
        <color
          rgba="1 1 1 1" />
      </material>
    </visual>
    <collision>
      <origin
        xyz="0 0 0"
        rpy="0 0 0" />
      <geometry>
        <mesh
          filename="package://gripper/meshes/link_1_left.STL" />
      </geometry>
    </collision>
  </link>

  <joint
    name="${prefix}_joint_1_left"
    type="revolute">
    <origin
      xyz="-0.01 -0.005 0.02925"
      rpy="1.5708 0 3.1416" />
    <parent
      link="${prefix}_mount_link" />
    <child
      link="${prefix}_link_1_left" />
    <axis
      xyz="0 0 -1" />
    <limit
      lower="-3.14"
      upper="3.14"
      effort="1"
      velocity="1" />
    <dynamics
      damping="1"
      friction="1" />
    <mimic
      joint="${prefix}_joint_1_right"
      multiplier="-1"
      offset="0" />
  </joint>

  <link
    name="${prefix}_link_2_left">
    <inertial>
      <origin
        xyz="-0.0118635948259238 0.0260158233367256 -9.35122738154528E-05"
        rpy="0 0 0" />
      <mass
        value="0.00437161591060403" />
      <inertia
        ixx="1.26241086249325E-06"
        ixy="4.50233056113258E-07"
        ixz="1.03279945421963E-09"
        iyy="2.54614187804496E-07"
        iyz="-1.94371719517842E-09"
        izz="1.49861390642806E-06" />
    </inertial>
    <visual>
      <origin
        xyz="0 0 0"
        rpy="0 0 0" />
      <geometry>
        <mesh
          filename="package://gripper/meshes/link_2_left.STL" />
      </geometry>
      <material
        name="">
        <color
          rgba="0.792156862745098 0.819607843137255 0.933333333333333 1" />
      </material>
    </visual>
    <collision>
      <origin
        xyz="0 0 0"
        rpy="0 0 0" />
      <geometry>
        <mesh
          filename="package://gripper/meshes/link_2_left.STL" />
      </geometry>
    </collision>
  </link>

  <joint
    name="${prefix}_joint_2_left"
    type="revolute">
    <origin
      xyz="0.05 0 0.005"
      rpy="0 0 0" />
    <parent
      link="${prefix}_link_1_left" />
    <child
      link="${prefix}_link_2_left" />
    <axis
      xyz="0 0 1" />
    <limit
      lower="-3.14"
      upper="3.14"
      effort="1"
      velocity="1" />
    <dynamics
      damping="1"
      friction="1" />
    <mimic
      joint="${prefix}_joint_1_left"
      multiplier="1"
      offset="0" />
  </joint>

  <link
    name="${prefix}_link_3_left">
    <inertial>
      <origin
        xyz="-0.00764323689249072 6.15392821018979E-19 -0.0158438878575795"
        rpy="0 0 0" />
      <mass
        value="0.00676809927823876" />
      <inertia
        ixx="6.50800323977911E-07"
        ixy="-2.76588985914095E-23"
        ixz="-1.32178480768053E-07"
        iyy="7.0118965410435E-07"
        iyz="-3.28680901965363E-23"
        izz="3.53298937602956E-07" />
    </inertial>
    <visual>
      <origin
        xyz="0 0 0"
        rpy="0 0 0" />
      <geometry>
        <mesh
          filename="package://gripper/meshes/link_3_left.STL" />
      </geometry>
      <material
        name="">
        <color
          rgba="0.298039215686275 0.298039215686275 0.298039215686275 1" />
      </material>
    </visual>
    <collision>
      <origin
        xyz="0 0 0"
        rpy="0 0 0" />
      <geometry>
        <mesh
          filename="package://gripper/meshes/link_3_left.STL" />
      </geometry>
    </collision>
  </link>

  <joint
    name="${prefix}_joint_3_left"
    type="fixed">
    <origin
      xyz="-0.029 0.061 0"
      rpy="1.5708 0 3.1416" />
    <parent
      link="${prefix}_link_2_left" />
    <child
      link="${prefix}_link_3_left" />
    <axis
      xyz="0 0 0" />
    <limit
      lower="-3.14"
      effort="0"
      velocity="0" />
  </joint>

  <link
    name="${prefix}_link_support_left">
    <inertial>
      <origin
        xyz="-0.0230443185065054 -1.92516886232946E-18 -0.00617590354942425"
        rpy="0 0 0" />
      <mass
        value="0.00343879121636352" />
      <inertia
        ixx="3.3013163060583E-07"
        ixy="-4.9675081730519E-23"
        ixz="-3.63783392132806E-07"
        iyy="9.95820730062242E-07"
        iyz="1.93019503238979E-23"
        izz="7.23002286395804E-07" />
    </inertial>
    <visual>
      <origin
        xyz="0 0 0"
        rpy="0 0 0" />
      <geometry>
        <mesh
          filename="package://gripper/meshes/link_support_left.STL" />
      </geometry>
      <material
        name="">
        <color
          rgba="1 1 1 1" />
      </material>
    </visual>
    <collision>
      <origin
        xyz="0 0 0"
        rpy="0 0 0" />
      <geometry>
        <mesh
          filename="package://gripper/meshes/link_support_left.STL" />
      </geometry>
    </collision>
  </link>

  <joint
    name="${prefix}_joint_support_left"
    type="revolute">
    <origin
      xyz="-0.004 0 0.04525"
      rpy="0 0.5236 0" />
    <parent
      link="${prefix}_mount_link" />
    <child
      link="${prefix}_link_support_left" />
    <axis
      xyz="0 1 0" />
    <limit
      lower="-3.14"
      upper="3.14"
      effort="1"
      velocity="1" />
    <dynamics
      damping="1"
      friction="1" />
    <mimic
      joint="${prefix}_joint_1_left"
      multiplier="-1"
      offset="0" />
  </joint>

  <link
    name="${prefix}_link_1_right">
    <inertial>
      <origin
        xyz="0.0216856425487956 -3.46944695195361E-18 0.000708029008234877"
        rpy="0 0 0" />
      <mass
        value="0.00477903641271765" />
      <inertia
        ixx="1.1732564402647E-07"
        ixy="-1.80664133980049E-23"
        ixz="6.51369632433988E-08"
        iyy="2.08980923685234E-06"
        iyz="-1.49480652486311E-23"
        izz="2.14169254123333E-06" />
    </inertial>
    <visual>
      <origin
        xyz="0 0 0"
        rpy="0 0 0" />
      <geometry>
        <mesh
          filename="package://gripper/meshes/link_1_right.STL" />
      </geometry>
      <material
        name="">
        <color
          rgba="1 1 1 1" />
      </material>
    </visual>
    <collision>
      <origin
        xyz="0 0 0"
        rpy="0 0 0" />
      <geometry>
        <mesh
          filename="package://gripper/meshes/link_1_right.STL" />
      </geometry>
    </collision>
  </link>

  <joint
    name="${prefix}_joint_1_right"
    type="revolute">
    <origin
      xyz="0.01 0 0.02925"
      rpy="1.5708 0 0" />
    <parent
      link="${prefix}_mount_link" />
    <child
      link="${prefix}_link_1_right" />
    <axis
      xyz="0 0 1" />
    <limit
      lower="0"
      upper="1"
      effort="1"
      velocity="1" />
    <dynamics
      damping="1"
      friction="1" />
  </joint>

  <link
    name="${prefix}_link_2_right">
    <inertial>
      <origin
        xyz="-0.0118635948259238 0.0260158233367256 9.35122738154512E-05"
        rpy="0 0 0" />
      <mass
        value="0.00437161591060403" />
      <inertia
        ixx="1.26241086249325E-06"
        ixy="4.50233056113258E-07"
        ixz="-1.03279945421962E-09"
        iyy="2.54614187804496E-07"
        iyz="1.9437171951784E-09"
        izz="1.49861390642806E-06" />
    </inertial>
    <visual>
      <origin
        xyz="0 0 0"
        rpy="0 0 0" />
      <geometry>
        <mesh
          filename="package://gripper/meshes/link_2_right.STL" />
      </geometry>
      <material
        name="">
        <color
          rgba="0.792156862745098 0.819607843137255 0.933333333333333 1" />
      </material>
    </visual>
    <collision>
      <origin
        xyz="0 0 0"
        rpy="0 0 0" />
      <geometry>
        <mesh
          filename="package://gripper/meshes/link_2_right.STL" />
      </geometry>
    </collision>
  </link>

  <joint
    name="${prefix}_joint_2_right"
    type="revolute">
    <origin
      xyz="0.05 0 0"
      rpy="0 0 0" />
    <parent
      link="${prefix}_link_1_right" />
    <child
      link="${prefix}_link_2_right" />
    <axis
      xyz="0 0 -1" />
    <limit
      lower="-3.14"
      upper="3.14"
      effort="1"
      velocity="1" />
    <dynamics
      damping="1"
      friction="1" />
    <mimic
      joint="${prefix}_joint_1_right"
      multiplier="1"
      offset="0" />
  </joint>

  <link
    name="${prefix}_link_3_right">
    <inertial>
      <origin
        xyz="0.00764323689249072 -6.70481136450209E-19 -0.0158438878575795"
        rpy="0 0 0" />
      <mass
        value="0.00676809927823876" />
      <inertia
        ixx="6.50800323977911E-07"
        ixy="-3.90699123108268E-23"
        ixz="1.32178480768053E-07"
        iyy="7.0118965410435E-07"
        iyz="-1.94350230005656E-23"
        izz="3.53298937602955E-07" />
    </inertial>
    <visual>
      <origin
        xyz="0 0 0"
        rpy="0 0 0" />
      <geometry>
        <mesh
          filename="package://gripper/meshes/link_3_right.STL" />
      </geometry>
      <material
        name="">
        <color
          rgba="0.298039215686275 0.298039215686275 0.298039215686275 1" />
      </material>
    </visual>
    <collision>
      <origin
        xyz="0 0 0"
        rpy="0 0 0" />
      <geometry>
        <mesh
          filename="package://gripper/meshes/link_3_right.STL" />
      </geometry>
    </collision>
  </link>

  <joint
    name="${prefix}_joint_3_right"
    type="fixed">
    <origin
      xyz="-0.029 0.061 0"
      rpy="-1.5708 0 0" />
    <parent
      link="${prefix}_link_2_right" />
    <child
      link="${prefix}_link_3_right" />
    <axis
      xyz="0 0 0" />
  </joint>

  <link
    name="${prefix}_link_support_right">
    <inertial>
      <origin
        xyz="-0.0230443185065054 2.00458308010044E-18 -0.00617590354942422"
        rpy="0 0 0" />
      <mass
        value="0.00343879121636352" />
      <inertia
        ixx="3.3013163060583E-07"
        ixy="1.63567262663565E-23"
        ixz="-3.63783392132805E-07"
        iyy="9.95820730062241E-07"
        iyz="2.40140706788198E-23"
        izz="7.23002286395803E-07" />
    </inertial>
    <visual>
      <origin
        xyz="0 0 0"
        rpy="0 0 0" />
      <geometry>
        <mesh
          filename="package://gripper/meshes/link_support_right.STL" />
      </geometry>
      <material
        name="">
        <color
          rgba="1 1 1 1" />
      </material>
    </visual>
    <collision>
      <origin
        xyz="0 0 0"
        rpy="0 0 0" />
      <geometry>
        <mesh
          filename="package://gripper/meshes/link_support_right.STL" />
      </geometry>
    </collision>
  </link>

  <joint
    name="${prefix}_joint_support_right"
    type="revolute">
    <origin
      xyz="0.004 0 0.04525"
      rpy="0 0.5236 -3.1416" />
    <parent
      link="${prefix}_mount_link" />
    <child
      link="${prefix}_link_support_right" />
    <axis
      xyz="0 1 0" />
    <limit
      lower="-3.14"
      upper="3.14"
      effort="1"
      velocity="1" />
    <dynamics
      damping="1"
      friction="1" />
    <mimic
      joint="${prefix}_joint_1_right"
      multiplier="1"
      offset="0" />
  </joint>

  </xacro:macro>

  <xacro:gripper prefix="gripper" /> <!-- parent-->

</robot>